Workbook

Sheet Meeting index
A2: Starfish and Vulcan API review
A4: Source rows | B4: 60 | D4: Tracked findings | E4: =COUNTA('API tracker'!A8:A85) -> 78
A6: Documentation Only | B6: =COUNTIF('API tracker'!K8:K85,"Documentation Only") -> 2 | D6: Firmware scope | F6: F-013: reviewer confirms a need; exact fields and release remain open.
A7: Schema Update | B7: =COUNTIF('API tracker'!K8:K85,"Schema Update") -> 21
A8: Firmware Change | B8: =COUNTIF('API tracker'!K8:K85,"Firmware Change") -> 1 | D8: Missing feedback | F8: Endpoint row 32 and field row 16 truncated. Kamali field rows 17–28 absent.
A9: Developer Clarification | B9: =COUNTIF('API tracker'!K8:K85,"Developer Clarification") -> 35
A10: No Change Required | B10: =COUNTIF('API tracker'!K8:K85,"No Change Required") -> 19 | D10: Review evidence | F10: Pinned repository snapshot and reviewer comments; no reader testing.
A12: Issue ID | B12: API Endpoint | C12: Method | D12: Change Type | E12: Status | F12: Finding | G12: Tracker row | H12: Walkthrough
A13: E-001 | B13: /cloud/ble-config | C13: GET | D13: ='API tracker'!K8 -> Documentation Only | E13: ='API tracker'!O8 -> Open | F13: BLE path spelling in the review | G13: =HYPERLINK("#'API tracker'!A8","Record decision") -> Record decision | H13: =HYPERLINK("Firmware_Change_Review.md#e-001","Open E-001") -> Open E-001
A14: E-002 | B14: /cloud/ble-config | C14: PUT | D14: ='API tracker'!K9 -> Documentation Only | E14: ='API tracker'!O9 -> Open | F14: BLE path spelling in the review | G14: =HYPERLINK("#'API tracker'!A9","Record decision") -> Record decision | H14: =HYPERLINK("Firmware_Change_Review.md#e-002","Open E-002") -> Open E-002
A15: E-003 | B15: /cloud/caCertificates | C15: GET | D15: ='API tracker'!K10 -> Developer Clarification | E15: ='API tracker'!O10 -> Open | F15: CA-certificate REST mapping and path contract | G15: =HYPERLINK("#'API tracker'!A10","Record decision") -> Record decision | H15: =HYPERLINK("Firmware_Change_Review.md#e-003","Open E-003") -> Open E-003
A16: E-004 | B16: /cloud/caCertificates/{caname} | C16: DELETE | D16: ='API tracker'!K11 -> Developer Clarification | E16: ='API tracker'!O11 -> Open | F16: CA-certificate REST mapping and path contract | G16: =HYPERLINK("#'API tracker'!A11","Record decision") -> Record decision | H16: =HYPERLINK("Firmware_Change_Review.md#e-004","Open E-004") -> Open E-004
A17: E-005 | B17: /cloud/caCertificates/{caname} | C17: PUT | D17: ='API tracker'!K12 -> Developer Clarification | E17: ='API tracker'!O12 -> Open | F17: CA-certificate REST mapping and path contract | G17: =HYPERLINK("#'API tracker'!A12","Record decision") -> Record decision | H17: =HYPERLINK("Firmware_Change_Review.md#e-005","Open E-005") -> Open E-005
A18: E-006 | B18: /cloud/eSimConfig | C18: GET | D18: ='API tracker'!K13 -> Developer Clarification | E18: ='API tracker'!O13 -> Open | F18: eSIM model applicability | G18: =HYPERLINK("#'API tracker'!A13","Record decision") -> Record decision | H18: =HYPERLINK("Firmware_Change_Review.md#e-006","Open E-006") -> Open E-006
A19: E-007 | B19: /cloud/eSimConfig | C19: PUT | D19: ='API tracker'!K14 -> Developer Clarification | E19: ='API tracker'!O14 -> Open | F19: eSIM model applicability | G19: =HYPERLINK("#'API tracker'!A14","Record decision") -> Record decision | H19: =HYPERLINK("Firmware_Change_Review.md#e-007","Open E-007") -> Open E-007
A20: E-008 | B20: /cloud/impinjGen2X | C20: GET | D20: ='API tracker'!K15 -> Developer Clarification | E20: ='API tracker'!O15 -> Open | F20: Dedicated Gen2X endpoint support | G20: =HYPERLINK("#'API tracker'!A15","Record decision") -> Record decision | H20: =HYPERLINK("Firmware_Change_Review.md#e-008","Open E-008") -> Open E-008
A21: E-009 | B21: /cloud/impinjGen2X | C21: PUT | D21: ='API tracker'!K16 -> Developer Clarification | E21: ='API tracker'!O16 -> Open | F21: Dedicated Gen2X endpoint support | G21: =HYPERLINK("#'API tracker'!A16","Record decision") -> Record decision | H21: =HYPERLINK("Firmware_Change_Review.md#e-009","Open E-009") -> Open E-009
A22: E-010 | B22: /cloud/localRestLogin | C22: GET | D22: ='API tracker'!K17 -> Schema Update | E22: ='API tracker'!O17 -> Open | F22: Missing Starfish login operation | G22: =HYPERLINK("#'API tracker'!A17","Record decision") -> Record decision | H22: =HYPERLINK("Firmware_Change_Review.md#e-010","Open E-010") -> Open E-010
A23: E-011 | B23: /cloud/logs/RcLog | C23: GET | D23: ='API tracker'!K18 -> No Change Required | E23: ='API tracker'!O18 -> Resolved | F23: Concrete log URL is already represented | G23: =HYPERLINK("#'API tracker'!A18","Record decision") -> Record decision | H23: =HYPERLINK("Firmware_Change_Review.md#e-011","Open E-011") -> Open E-011
A24: E-012 | B24: /cloud/logs/RgErrorLog | C24: GET | D24: ='API tracker'!K19 -> No Change Required | E24: ='API tracker'!O19 -> Resolved | F24: Concrete log URL is already represented | G24: =HYPERLINK("#'API tracker'!A19","Record decision") -> Record decision | H24: =HYPERLINK("Firmware_Change_Review.md#e-012","Open E-012") -> Open E-012
A25: E-013 | B25: /cloud/logs/RgWarningLog | C25: GET | D25: ='API tracker'!K20 -> No Change Required | E25: ='API tracker'!O20 -> Resolved | F25: Concrete log URL is already represented | G25: =HYPERLINK("#'API tracker'!A20","Record decision") -> Record decision | H25: =HYPERLINK("Firmware_Change_Review.md#e-013","Open E-013") -> Open E-013
A26: E-014 | B26: /cloud/logs/radioPacketLog | C26: DELETE | D26: ='API tracker'!K21 -> No Change Required | E26: ='API tracker'!O21 -> Resolved | F26: Concrete log URL is already represented | G26: =HYPERLINK("#'API tracker'!A21","Record decision") -> Record decision | H26: =HYPERLINK("Firmware_Change_Review.md#e-014","Open E-014") -> Open E-014
A27: E-015 | B27: /cloud/logs/radioPacketLog | C27: GET | D27: ='API tracker'!K22 -> No Change Required | E27: ='API tracker'!O22 -> Resolved | F27: Concrete log URL is already represented | G27: =HYPERLINK("#'API tracker'!A22","Record decision") -> Record decision | H27: =HYPERLINK("Firmware_Change_Review.md#e-015","Open E-015") -> Open E-015
A28: E-016 | B28: /cloud/logs/syslog | C28: DELETE | D28: ='API tracker'!K23 -> No Change Required | E28: ='API tracker'!O23 -> Resolved | F28: Concrete log URL is already represented | G28: =HYPERLINK("#'API tracker'!A23","Record decision") -> Record decision | H28: =HYPERLINK("Firmware_Change_Review.md#e-016","Open E-016") -> Open E-016
A29: E-017 | B29: /cloud/logs/syslog | C29: GET | D29: ='API tracker'!K24 -> No Change Required | E29: ='API tracker'!O24 -> Resolved | F29: Concrete log URL is already represented | G29: =HYPERLINK("#'API tracker'!A24","Record decision") -> Record decision | H29: =HYPERLINK("Firmware_Change_Review.md#e-017","Open E-017") -> Open E-017
A30: E-018 | B30: /cloud/networkInterfaces | C30: GET | D30: ='API tracker'!K25 -> No Change Required | E30: ='API tracker'!O25 -> Resolved | F30: Intentional platform scope | G30: =HYPERLINK("#'API tracker'!A25","Record decision") -> Record decision | H30: =HYPERLINK("Firmware_Change_Review.md#e-018","Open E-018") -> Open E-018
A31: E-019 | B31: /cloud/pass-through | C31: PUT | D31: ='API tracker'!K26 -> Schema Update | E31: ='API tracker'!O26 -> Open | F31: Missing Starfish component pass-through documentation | G31: =HYPERLINK("#'API tracker'!A26","Record decision") -> Record decision | H31: =HYPERLINK("Firmware_Change_Review.md#e-019","Open E-019") -> Open E-019
A32: E-020 | B32: /cloud/preSelection | C32: GET | D32: ='API tracker'!K27 -> No Change Required | E32: ='API tracker'!O27 -> Resolved | F32: Intentional platform scope | G32: =HYPERLINK("#'API tracker'!A27","Record decision") -> Record decision | H32: =HYPERLINK("Firmware_Change_Review.md#e-020","Open E-020") -> Open E-020
A33: E-021 | B33: /cloud/preSelection | C33: PUT | D33: ='API tracker'!K28 -> No Change Required | E33: ='API tracker'!O28 -> Resolved | F33: Intentional platform scope | G33: =HYPERLINK("#'API tracker'!A28","Record decision") -> Record decision | H33: =HYPERLINK("Firmware_Change_Review.md#e-021","Open E-021") -> Open E-021
A34: E-022 | B34: /cloud/readPoints | C34: GET | D34: ='API tracker'!K29 -> Developer Clarification | E34: ='API tracker'!O29 -> Open | F34: Internal read-points support versus public REST | G34: =HYPERLINK("#'API tracker'!A29","Record decision") -> Record decision | H34: =HYPERLINK("Firmware_Change_Review.md#e-022","Open E-022") -> Open E-022
A35: E-023 | B35: /cloud/readerLocation | C35: GET | D35: ='API tracker'!K30 -> No Change Required | E35: ='API tracker'!O30 -> Resolved | F35: Intentional platform scope | G35: =HYPERLINK("#'API tracker'!A30","Record decision") -> Record decision | H35: =HYPERLINK("Firmware_Change_Review.md#e-023","Open E-023") -> Open E-023
A36: E-024 | B36: /cloud/region | C36: PUT | D36: ='API tracker'!K31 -> Developer Clarification | E36: ='API tracker'!O31 -> Open | F36: Region setter release status | G36: =HYPERLINK("#'API tracker'!A31","Record decision") -> Record decision | H36: =HYPERLINK("Firmware_Change_Review.md#e-024","Open E-024") -> Open E-024
A37: E-025 | B37: /cloud/stack-led | C37: GET | D37: ='API tracker'!K32 -> No Change Required | E37: ='API tracker'!O32 -> Resolved | F37: Stack LED scope already narrowed | G37: =HYPERLINK("#'API tracker'!A32","Record decision") -> Record decision | H37: =HYPERLINK("Firmware_Change_Review.md#e-025","Open E-025") -> Open E-025
A38: E-026 | B38: /cloud/stack-led | C38: PUT | D38: ='API tracker'!K33 -> No Change Required | E38: ='API tracker'!O33 -> Resolved | F38: Stack LED scope already narrowed | G38: =HYPERLINK("#'API tracker'!A33","Record decision") -> Record decision | H38: =HYPERLINK("Firmware_Change_Review.md#e-026","Open E-026") -> Open E-026
A39: E-027 | B39: /cloud/updatePassword | C39: PUT | D39: ='API tracker'!K34 -> No Change Required | E39: ='API tracker'!O34 -> Resolved | F39: Intentional platform scope | G39: =HYPERLINK("#'API tracker'!A34","Record decision") -> Record decision | H39: =HYPERLINK("Firmware_Change_Review.md#e-027","Open E-027") -> Open E-027
A40: E-028 | B40: /cloud/wifiNetworks | C40: GET | D40: ='API tracker'!K35 -> No Change Required | E40: ='API tracker'!O35 -> Resolved | F40: Intentional platform scope | G40: =HYPERLINK("#'API tracker'!A35","Record decision") -> Record decision | H40: =HYPERLINK("Firmware_Change_Review.md#e-028","Open E-028") -> Open E-028
A41: E-029 | B41: /cloud/logs/{logType} | C41: DELETE | D41: ='API tracker'!K36 -> Developer Clarification | E41: ='API tracker'!O36 -> Open | F41: Log DELETE route and supported log types | G41: =HYPERLINK("#'API tracker'!A36","Record decision") -> Record decision | H41: =HYPERLINK("Firmware_Change_Review.md#e-029","Open E-029") -> Open E-029
A42: E-030 | B42: /cloud/logs/{logType} | C42: GET | D42: ='API tracker'!K37 -> Developer Clarification | E42: ='API tracker'!O37 -> Open | F42: Log retrieval response format and route mapping | G42: =HYPERLINK("#'API tracker'!A37","Record decision") -> Record decision | H42: =HYPERLINK("Firmware_Change_Review.md#e-030","Open E-030") -> Open E-030
A43: E-031 | B43: /cloud/nameAndDescription | C43: GET | D43: ='API tracker'!K38 -> No Change Required | E43: ='API tracker'!O38 -> Resolved | F43: Intentional platform scope | G43: =HYPERLINK("#'API tracker'!A38","Record decision") -> Record decision | H43: =HYPERLINK("Firmware_Change_Review.md#e-031","Open E-031") -> Open E-031
A44: E-032 | B44: /cloud/nameAndDescription | C44: PUT | D44: ='API tracker'!K39 -> Developer Clarification | E44: ='API tracker'!O39 -> Open | F44: Truncated PUT name-and-description feedback | G44: =HYPERLINK("#'API tracker'!A39","Record decision") -> Record decision | H44: =HYPERLINK("Firmware_Change_Review.md#e-032","Open E-032") -> Open E-032
...

Sheet API tracker
A2: API review tracker
A4: Amber cells: record developer decisions, then update Change Type and Status. Keep source feedback unchanged.
A5: Scope: 60 source rows. No live reader tests supplied. Firmware confirmation for F-013 is endpoint-level only; exact code changes remain open.
A7: Issue ID | B7: Original Comment | C7: API Endpoint | D7: HTTP Method | E7: Platform | F7: Schema Path | G7: Starfish Behavior | H7: Vulcan Behavior | I7: Identified Difference | J7: Expected Behavior | K7: Change Type | L7: Required Action | M7: Developer Question | N7: Developer Confirmation | O7: Status | P7: Source Reference | Q7: Developer Walkthrough | R7: Finding | S7: Evidence / Limitations
A8: E-001 | B8: Starfish: Firmware confirms FX9600 does not support it. Kamali: supported only in fxr90/60 | C8: /cloud/ble-config | D8: GET | E8: Vulcan | F8: Starfish: Operation absent -> #/paths/~1cloud~1ble-config/get Vulcan: $["ble"] -> #/components/schemas/GetBleConfigResponse/properties/ble Vulcan: $["ble"]["enable"] -> #/components/schemas/GetBleConfigResponse/properties/ble/properties/enable Vulcan: $["ble"]["scanIntervalSec"] -> #/components/schemas/GetBleConfigResponse/properties/ble/properties/scanIntervalSec | G8: No operation in supplied schema; implementation is not established by that absence. | H8: Documented GET /cloud/bleConfig. Get BLE configuration. Parameters: none declared. Request: none declared. Success: 200 [application/json]: type="object". | I8: Workbook uses /cloud/ble-config; the current Vulcan schema and narrative use /cloud/bleConfig. Both reviewers exclude FX9600. | J8: Use the documented /cloud/bleConfig spelling and retain FXR60/FXR90 applicability. | K8: Documentation Only | L8: Correct the endpoint label in the consolidated review and cross-references; do not create an alias endpoint. | M8: No behavior decision is needed for the spelling correction. If /cloud/ble-config is intended as a supported alias, provide an actual request result and firmware version. | N8: Not yet recorded | O8: Open | P8: Endpoint review, source 1, Excel row 7 | Q8: =HYPERLINK("Firmware_Change_Review.md#e-001","Open E-001") -> Open E-001 | R8: BLE path spelling in the review | S8: Both reviewers confirm FXR-only support; Vulcan operation description and path agree on /cloud/bleConfig. Source limitation: Path spelling retained from source; verify against the approved schema.
A9: E-002 | B9: Starfish: Firmware confirms FX9600 does not support it. Kamali: supported only in fxr90/60 | C9: /cloud/ble-config | D9: PUT | E9: Vulcan | F9: Starfish: Operation absent -> #/paths/~1cloud~1ble-config/put Vulcan: $["ble"] -> #/components/schemas/SetBleConfigRequest/properties/ble Vulcan: $["ble"]["enable"] -> #/components/schemas/SetBleConfigRequest/properties/ble/properties/enable Vulcan: $["ble"]["scanIntervalSec"] -> #/components/schemas/SetBleConfigRequest/properties/ble/properties/scanIntervalSec | G9: No operation in supplied schema; implementation is not established by that absence. | H9: Documented PUT /cloud/bleConfig. Set BLE configuration. Parameters: none declared. Request: type="object"; required=["ble"]. Success: 200 []: no body schema. | I9: Workbook uses /cloud/ble-config; the current Vulcan schema and narrative use /cloud/bleConfig. Both reviewers exclude FX9600. | J9: Use the documented /cloud/bleConfig spelling and retain FXR60/FXR90 applicability. | K9: Documentation Only | L9: Correct the endpoint label in the consolidated review and cross-references; do not create an alias endpoint. | M9: No behavior decision is needed for the spelling correction. If /cloud/ble-config is intended as a supported alias, provide an actual request result and firmware version. | N9: Not yet recorded | O9: Open | P9: Endpoint review, source 2, Excel row 8 | Q9: =HYPERLINK("Firmware_Change_Review.md#e-002","Open E-002") -> Open E-002 | R9: BLE path spelling in the review | S9: Both reviewers confirm FXR-only support; Vulcan operation description and path agree on /cloud/bleConfig. Source limitation: Path spelling retained from source; verify against the approved schema.
A10: E-003 | B10: Starfish: FX9600 supports this (undocumented) Kamali: not supported in fx9600 (local rest mapping missing ,mqtt available) | C10: /cloud/caCertificates | D10: GET | E10: Both | F10: Starfish: Operation absent -> #/paths/~1cloud~1caCertificates/get Vulcan: $ -> #/components/schemas/caCertificateList.v1 Vulcan: $[*] -> #/components/schemas/caCertificateList.v1/items | G10: No operation in supplied schema; implementation is not established by that absence. | H10: Documented GET /cloud/caCertificates. List installed CA certificates. Parameters: none declared. Request: none declared. Success: 200 [application/json]: type="array". | I10: Starfish says FX9600 supports this REST operation; Kamali says local REST mapping is missing while MQTT exists. Starfish has no operation in this snapshot. | J10: Public REST support and the accepted URL/body must be established separately for each method and firmware release. | K10: Developer Clarification | L10: Obtain a local REST request/response on FX9600. If supported, add its schema. If absent, decide whether REST exposure is an approved firmware requirement. Preserve MQTT scope separately. | M10: On which FX9600 firmware does GET CA-certificate management work over local REST? Is the accepted URL /cloud/caCertificates or /cloud/caCertificates/{caname}, and is the certificate name in JSON name or the path? If no mapping exists, is adding it required? | N10: Not yet recorded | O10: Open | P10: Endpoint review, source 3, Excel row 9 | Q10: =HYPERLINK("Firmware_Change_Review.md#e-003","Open E-003") -> Open E-003 | R10: CA-certificate REST mapping and path contract | S10: Repository schema and original reviewer statements; no live reader test supplied. Source limitation: MQTT availability does not confirm local REST support.
A11: E-004 | B11: Starfish: FX9600 supports this (undocumented) Kamali: not supported in fx9600 (local rest mapping missing ,mqtt available) | C11: /cloud/caCertificates/{caname} | D11: DELETE | E11: Both | F11: Starfish: Operation absent -> #/paths/~1cloud~1caCertificates/delete Vulcan: $ -> #/components/schemas/deleteCACertificate.v1 Vulcan: $["name"] -> #/components/schemas/deleteCACertificate.v1/properties/name | G11: No operation in supplied schema; implementation is not established by that absence. | H11: Documented DELETE /cloud/caCertificates. Delete CA certificate. Parameters: none declared. Request: type="object"; required=["name"]. Success: 200 [application/json]: type="string". | I11: Starfish says FX9600 supports this REST operation; Kamali says local REST mapping is missing while MQTT exists. Starfish has no operation in this snapshot. The workbook path /cloud/caCertificates/{caname} is absent in both files. Vulcan instead uses DELETE /cloud/caCertificates with JSON name; its description says caname is rejected. | J11: Public REST support and the accepted URL/body must be established separately for each method and firmware release. | K11: Developer Clarification | L11: Obtain a local REST request/response on FX9600. If supported, add its schema. If absent, decide whether REST exposure is an approved firmware requirement. Preserve MQTT scope separately. | M11: On which FX9600 firmware does DELETE CA-certificate management work over local REST? Is the accepted URL /cloud/caCertificates or /cloud/caCertificates/{caname}, and is the certificate name in JSON name or the path? If no mapping exists, is adding it required? | N11: Not yet recorded | O11: Open | P11: Endpoint review, source 4, Excel row 10 | Q11: =HYPERLINK("Firmware_Change_Review.md#e-004","Open E-004") -> Open E-004 | R11: CA-certificate REST mapping and path contract | S11: Repository schema and original reviewer statements; no live reader test supplied. Source limitation: MQTT availability does not confirm local REST support.
A12: E-005 | B12: Starfish: FX9600 supports this (undocumented) Kamali: not supported in fx9600 (local rest mapping missing ,mqtt available) | C12: /cloud/caCertificates/{caname} | D12: PUT | E12: Both | F12: Starfish: Operation absent -> #/paths/~1cloud~1caCertificates/put Vulcan: $ -> #/components/schemas/installCACertificate.v1 Vulcan: $["name"] -> #/components/schemas/installCACertificate.v1/properties/name Vulcan: $["content"] -> #/components/schemas/installCACertificate.v1/properties/content | G12: No operation in supplied schema; implementation is not established by that absence. | H12: Documented PUT /cloud/caCertificates. Install CA certificate. Parameters: none declared. Request: type="object"; required=["name","content"]. Success: 200 [application/json]: type="string". | I12: Starfish says FX9600 supports this REST operation; Kamali says local REST mapping is missing while MQTT exists. Starfish has no operation in this snapshot. The workbook path /cloud/caCertificates/{caname} is absent in both files. Vulcan instead uses PUT /cloud/caCertificates with JSON name and content. | J12: Public REST support and the accepted URL/body must be established separately for each method and firmware release. | K12: Developer Clarification | L12: Obtain a local REST request/response on FX9600. If supported, add its schema. If absent, decide whether REST exposure is an approved firmware requirement. Preserve MQTT scope separately. | M12: On which FX9600 firmware does PUT CA-certificate management work over local REST? Is the accepted URL /cloud/caCertificates or /cloud/caCertificates/{caname}, and is the certificate name in JSON name or the path? If no mapping exists, is adding it required? | N12: Not yet recorded | O12: Open | P12: Endpoint review, source 5, Excel row 11 | Q12: =HYPERLINK("Firmware_Change_Review.md#e-005","Open E-005") -> Open E-005 | R12: CA-certificate REST mapping and path contract | S12: Repository schema and original reviewer statements; no live reader test supplied. Source limitation: MQTT availability does not confirm local REST support.
A13: E-006 | B13: Starfish: Firmware confirms FX9600 does not support it. Kamali: supported only in fxr90/60 | C13: /cloud/eSimConfig | D13: GET | E13: Vulcan | F13: Starfish: Operation absent -> #/paths/~1cloud~1eSimConfig/get Vulcan: $["eid"] -> #/components/schemas/GetEsimConfigResponse/properties/eid Vulcan: $["imei"] -> #/components/schemas/GetEsimConfigResponse/properties/imei Vulcan: $["profiles"] -> #/components/schemas/GetEsimConfigResponse/properties/profiles | G13: No operation in supplied schema; implementation is not established by that absence. | H13: Documented GET /cloud/eSimConfig. Gets the eSIM configuration. Parameters: none declared. Request: none declared. Success: 200 [application/json]: type="object". | I13: Both reviewers describe FXR60/FXR90 support, but the current Vulcan narrative explicitly says FXR90 only. Starfish has no eSIM operation. | J13: Keep FX9600 excluded. Establish whether any FXR60 variant supports this eSIM operation. | K13: Developer Clarification | L13: Resolve the model scope before changing Applies To or promising FXR60 support. | M13: Does eSIM configuration apply exclusively to FXR90 as the current description states, or to a specific FXR60 SKU too? Identify the supported model and firmware. | N13: Not yet recorded | O13: Open | P13: Endpoint review, source 6, Excel row 12 | Q13: =HYPERLINK("Firmware_Change_Review.md#e-006","Open E-006") -> Open E-006 | R13: eSIM model applicability | S13: Repository schema and original reviewer statements; no live reader test supplied.
A14: E-007 | B14: Starfish: Firmware confirms FX9600 does not support it. Kamali: supported only in fxr90/60 | C14: /cloud/eSimConfig | D14: PUT | E14: Vulcan | F14: Starfish: Operation absent -> #/paths/~1cloud~1eSimConfig/put Vulcan: $["operation"] -> #/components/schemas/SetEsimConfigRequest/properties/operation Vulcan: $["profileNickName"] -> #/components/schemas/SetEsimConfigRequest/properties/profileNickName Vulcan: $["activationID"] -> #/components/schemas/SetEsimConfigRequest/properties/activationID | G14: No operation in supplied schema; implementation is not established by that absence. | H14: Documented PUT /cloud/eSimConfig. Sets the eSIM configuration. Parameters: none declared. Request: type="object"; required=["operation","profileNickName"]. Success: 200 [application/json]: type="string". | I14: Both reviewers describe FXR60/FXR90 support, but the current Vulcan narrative explicitly says FXR90 only. Starfish has no eSIM operation. | J14: Keep FX9600 excluded. Establish whether any FXR60 variant supports this eSIM operation. | K14: Developer Clarification | L14: Resolve the model scope before changing Applies To or promising FXR60 support. | M14: Does eSIM configuration apply exclusively to FXR90 as the current description states, or to a specific FXR60 SKU too? Identify the supported model and firmware. | N14: Not yet recorded | O14: Open | P14: Endpoint review, source 7, Excel row 13 | Q14: =HYPERLINK("Firmware_Change_Review.md#e-007","Open E-007") -> Open E-007 | R14: eSIM model applicability | S14: Repository schema and original reviewer statements; no live reader test supplied.
A15: E-008 | B15: Starfish: FX9600 supports this (undocumented) Kamali: supported only in fxr90/60 | C15: /cloud/impinjGen2X | D15: GET | E15: Starfish | F15: Starfish: Operation absent -> #/paths/~1cloud~1impinjGen2X/get Vulcan: $["fastID"] -> #/components/schemas/GetImpinjGen2XResponse/properties/fastID Vulcan: $["fastID"]["enabled"] -> #/components/schemas/GetImpinjGen2XResponse/properties/fastID/properties/enabled Vulcan: $["tagProtect"] -> #/components/schemas/GetImpinjGen2XResponse/properties/tagProtect Vulcan: $["tagFocus"] -> #/components/schemas/GetImpinjGen2XResponse/properties/tagFocus Vulcan: $["tagQuieting"] -> #/components/schemas/impinjTagQuieting.v1 | G15: No operation in supplied schema; implementation is not established by that absence. | H15: Documented GET /cloud/impinjGen2X. Get Impinj Gen2X configuration. Parameters: none declared. Request: none declared. Success: 200 [application/json]: type="object". | I15: Starfish reports undocumented FX9600 support, while Kamali says FXR60/FXR90 only. The dedicated operation is absent from the Starfish specification. | J15: Establish GET /cloud/impinjGen2X support independently of applyImpinjGen2X in /start and impinjGen2X in /status. | K15: Developer Clarification | L15: Request a firmware-versioned local REST example. Add schema if implemented; create a firmware requirement only if the missing dedicated operation is approved. | M15: Does FX9600 implement GET /cloud/impinjGen2X on the target release? Supply the accepted request/returned object and status code, or confirm that only start/status Gen2X integration exists. | N15: Not yet recorded | O15: Open | P15: Endpoint review, source 8, Excel row 14 | Q15: =HYPERLINK("Firmware_Change_Review.md#e-008","Open E-008") -> Open E-008 | R15: Dedicated Gen2X endpoint support | S15: Repository schema and original reviewer statements; no live reader test supplied. Source limitation: Gen2X fields in /start and /status do not establish support for this endpoint.
A16: E-009 | B16: Starfish: FX9600 supports this (undocumented) Kamali: supported only in fxr90/60 | C16: /cloud/impinjGen2X | D16: PUT | E16: Starfish | F16: Starfish: Operation absent -> #/paths/~1cloud~1impinjGen2X/put Vulcan: $["fastID"] -> #/components/schemas/SetImpinjGen2XRequest/properties/fastID Vulcan: $["fastID"]["enabled"] -> #/components/schemas/SetImpinjGen2XRequest/properties/fastID/properties/enabled Vulcan: $["tagProtect"] -> #/components/schemas/SetImpinjGen2XRequest/properties/tagProtect Vulcan: $["tagFocus"] -> #/components/schemas/SetImpinjGen2XRequest/properties/tagFocus Vulcan: $["tagQuieting"] -> #/components/schemas/impinjTagQuieting.v1 | G16: No operation in supplied schema; implementation is not established by that absence. | H16: Documented PUT /cloud/impinjGen2X. Set Impinj Gen2X configuration. Parameters: none declared. Request: type="object". Success: 200 [application/json]: type="object"; required=["message"]. | I16: Starfish reports undocumented FX9600 support, while Kamali says FXR60/FXR90 only. The dedicated operation is absent from the Starfish specification. | J16: Establish PUT /cloud/impinjGen2X support independently of applyImpinjGen2X in /start and impinjGen2X in /status. | K16: Developer Clarification | L16: Request a firmware-versioned local REST example. Add schema if implemented; create a firmware requirement only if the missing dedicated operation is approved. | M16: Does FX9600 implement PUT /cloud/impinjGen2X on the target release? Supply the accepted request/returned object and status code, or confirm that only start/status Gen2X integration exists. | N16: Not yet recorded | O16: Open | P16: Endpoint review, source 9, Excel row 15 | Q16: =HYPERLINK("Firmware_Change_Review.md#e-009","Open E-009") -> Open E-009 | R16: Dedicated Gen2X endpoint support | S16: Repository schema and original reviewer statements; no live reader test supplied. Source limitation: Gen2X fields in /start and /status do not establish support for this endpoint.
A17: E-010 | B17: Starfish: FX9600 supports this (undocumented) Kamali: supported in fx9600 undocumented | C17: /cloud/localRestLogin | D17: GET | E17: Starfish | F17: Starfish: Operation absent -> #/paths/~1cloud~1localRestLogin/get Vulcan: $ -> #/components/schemas/LocalrestloginResponse Vulcan: $["code"] -> #/components/schemas/LocalrestloginResponse/properties/code Vulcan: $["message"] -> #/components/schemas/LocalrestloginResponse/properties/message | G17: No operation in supplied schema; implementation is not established by that absence. | H17: Documented GET /cloud/localRestLogin. Reader Login. Parameters: none declared. Request: none declared. Success: 200 [application/json]: type="object". | I17: Both reviewers confirm FX9600 local REST login, but Starfish paths omit GET /cloud/localRestLogin. Vulcan documents code and message. | J17: Document the existing Starfish authentication operation using its actual response and authentication scheme. | K17: Schema Update | L17: Add the missing Starfish path and narrative after obtaining its token response. Do not copy a live token or infer identical token semantics. | M17: For the supported FX9600 firmware, does this GET use Basic authentication and return {code,message} as Vulcan does? Supply a redacted example and error responses. | N17: Not yet recorded | O17: Open | P17: Endpoint review, source 10, Excel row 16 | Q17: =HYPERLINK("Firmware_Change_Review.md#e-010","Open E-010") -> Open E-010 | R17: Missing Starfish login operation | S17: Repository schema and original reviewer statements; no live reader test supplied.
A18: E-011 | B18: Starfish: FX9600 supports this (documented) 9600 supports Delete /cloud/logs/{logType} for log types "syslog" "radioPacketLog" and Get /cloud/logs/{logType} for log types "syslog" "radioPacketLog" "RgErrorLog" "RgWarningLog" "RcLog" Kamali: supported in fx9600 undocumented | C18: /cloud/logs/RcLog | D18: GET | E18: Both | F18: Starfish: path logType -> #/paths/~1cloud~1logs~1{logType}/parameters/0 Starfish: $ -> #/paths/~1cloud~1logs~1{logType}/get/responses/200/content/application~1gzip/schema Vulcan: $ -> #/components/schemas/GetRcLogResponse Vulcan: $["binary"] -> #/components/schemas/GetRcLogResponse/properties/binary Vulcan: $["filename"] -> #/components/schemas/GetRcLogResponse/properties/filename | G18: Documented GET /cloud/logs/{logType}. Retrieve Log. Parameters: path logType. Request: none declared. Success: 200 [application/gzip]: type/constraints not specified here. | H18: Documented GET /cloud/logs/RcLog. Retrieve RcInfoLog. Parameters: none declared. Request: none declared. Success: 200 [application/json]: type="object". | I18: Starfish represents this URL as /cloud/logs/{logType}; its enum includes RcLog. Vulcan documents the concrete URL. Both reviewers report support. | J18: Retain both documentation representations. They describe the same concrete route for this log type. | K18: No Change Required | L18: No endpoint implementation change. In a unified index, link the concrete URL to the parameterized Starfish operation. Response-format and DELETE-enum questions are tracked in E-030 and E-029. | M18: None for this route-support finding. See E-029/E-030 for unresolved contracts. | N18: Not yet recorded | O18: Resolved | P18: Endpoint review, source 11, Excel row 17 | Q18: =HYPERLINK("Firmware_Change_Review.md#e-011","Open E-011") -> Open E-011 | R18: Concrete log URL is already represented | S18: Both reviewer statements confirm support; both operation definitions represent the concrete URL. This closure covers route presence only. Source limitation: Reviewers disagree on documented versus undocumented, not on support.
A19: E-012 | B19: Starfish: FX9600 supports this (documented) Kamali: supported in fx9600 undocumented | C19: /cloud/logs/RgErrorLog | D19: GET | E19: Both | F19: Starfish: path logType -> #/paths/~1cloud~1logs~1{logType}/parameters/0 Starfish: $ -> #/paths/~1cloud~1logs~1{logType}/get/responses/200/content/application~1gzip/schema Vulcan: $ -> #/components/schemas/GetRgErrorLogResponse Vulcan: $["binary"] -> #/components/schemas/GetRgErrorLogResponse/properties/binary Vulcan: $["filename"] -> #/components/schemas/GetRgErrorLogResponse/properties/filename | G19: Documented GET /cloud/logs/{logType}. Retrieve Log. Parameters: path logType. Request: none declared. Success: 200 [application/gzip]: type/constraints not specified here. | H19: Documented GET /cloud/logs/RgErrorLog. Retrieve RgErrorLog. Parameters: none declared. Request: none declared. Success: 200 [application/json]: type="object". | I19: Starfish represents this URL as /cloud/logs/{logType}; its enum includes RgErrorLog. Vulcan documents the concrete URL. Both reviewers report support. | J19: Retain both documentation representations. They describe the same concrete route for this log type. | K19: No Change Required | L19: No endpoint implementation change. In a unified index, link the concrete URL to the parameterized Starfish operation. Response-format and DELETE-enum questions are tracked in E-030 and E-029. | M19: None for this route-support finding. See E-029/E-030 for unresolved contracts. | N19: Not yet recorded | O19: Resolved | P19: Endpoint review, source 12, Excel row 18 | Q19: =HYPERLINK("Firmware_Change_Review.md#e-012","Open E-012") -> Open E-012 | R19: Concrete log URL is already represented | S19: Both reviewer statements confirm support; both operation definitions represent the concrete URL. This closure covers route presence only. Source limitation: Reviewers disagree on documented versus undocumented, not on support.
A20: E-013 | B20: Starfish: FX9600 supports this (documented) Kamali: supported in fx9600 undocumented | C20: /cloud/logs/RgWarningLog | D20: GET | E20: Both | F20: Starfish: path logType -> #/paths/~1cloud~1logs~1{logType}/parameters/0 Starfish: $ -> #/paths/~1cloud~1logs~1{logType}/get/responses/200/content/application~1gzip/schema Vulcan: $ -> #/components/schemas/GetRgWarningLogResponse Vulcan: $["binary"] -> #/components/schemas/GetRgWarningLogResponse/properties/binary Vulcan: $["filename"] -> #/components/schemas/GetRgWarningLogResponse/properties/filename | G20: Documented GET /cloud/logs/{logType}. Retrieve Log. Parameters: path logType. Request: none declared. Success: 200 [application/gzip]: type/constraints not specified here. | H20: Documented GET /cloud/logs/RgWarningLog. Retrieve RgWarningLog. Parameters: none declared. Request: none declared. Success: 200 [application/json]: type="object". | I20: Starfish represents this URL as /cloud/logs/{logType}; its enum includes RgWarningLog. Vulcan documents the concrete URL. Both reviewers report support. | J20: Retain both documentation representations. They describe the same concrete route for this log type. | K20: No Change Required | L20: No endpoint implementation change. In a unified index, link the concrete URL to the parameterized Starfish operation. Response-format and DELETE-enum questions are tracked in E-030 and E-029. | M20: None for this route-support finding. See E-029/E-030 for unresolved contracts. | N20: Not yet recorded | O20: Resolved | P20: Endpoint review, source 13, Excel row 19 | Q20: =HYPERLINK("Firmware_Change_Review.md#e-013","Open E-013") -> Open E-013 | R20: Concrete log URL is already represented | S20: Both reviewer statements confirm support; both operation definitions represent the concrete URL. This closure covers route presence only. Source limitation: Reviewers disagree on documented versus undocumented, not on support.
A21: E-014 | B21: Starfish: FX9600 supports this (documented) Kamali: supported in fx9600 undocumented | C21: /cloud/logs/radioPacketLog | D21: DELETE | E21: Both | F21: Starfish: path logType -> #/paths/~1cloud~1logs~1{logType}/parameters/0 Vulcan: No target field declared -> #/paths/~1cloud~1logs~1radioPacketLog/delete | G21: Documented DELETE /cloud/logs/{logType}. Purge Log. Parameters: path logType. Request: none declared. Success: 200 []: no body schema. | H21: Documented DELETE /cloud/logs/radioPacketLog. Purge Log. Parameters: none declared. Request: none declared. Success: 200 [application/json]: no body schema. | I21: Starfish represents this URL as /cloud/logs/{logType}; its enum includes radioPacketLog. Vulcan documents the concrete URL. Both reviewers report support. | J21: Retain both documentation representations. They describe the same concrete route for this log type. | K21: No Change Required | L21: No endpoint implementation change. In a unified index, link the concrete URL to the parameterized Starfish operation. Response-format and DELETE-enum questions are tracked in E-030 and E-029. | M21: None for this route-support finding. See E-029/E-030 for unresolved contracts. | N21: Not yet recorded | O21: Resolved | P21: Endpoint review, source 14, Excel row 20 | Q21: =HYPERLINK("Firmware_Change_Review.md#e-014","Open E-014") -> Open E-014 | R21: Concrete log URL is already represented | S21: Both reviewer statements confirm support; both operation definitions represent the concrete URL. This closure covers route presence only. Source limitation: Reviewers disagree on documented versus undocumented, not on support.
A22: E-015 | B22: Starfish: FX9600 supports this (documented) Kamali: supported in fx9600 undocumented | C22: /cloud/logs/radioPacketLog | D22: GET | E22: Both | F22: Starfish: path logType -> #/paths/~1cloud~1logs~1{logType}/parameters/0 Starfish: $ -> #/paths/~1cloud~1logs~1{logType}/get/responses/200/content/application~1gzip/schema Vulcan: $ -> #/components/schemas/GetRadioPacketLogResponse Vulcan: $["binary"] -> #/components/schemas/GetRadioPacketLogResponse/properties/binary Vulcan: $["filename"] -> #/components/schemas/GetRadioPacketLogResponse/properties/filename | G22: Documented GET /cloud/logs/{logType}. Retrieve Log. Parameters: path logType. Request: none declared. Success: 200 [application/gzip]: type/constraints not specified here. | H22: Documented GET /cloud/logs/radioPacketLog. Retrieve radioPacketLog. Parameters: none declared. Request: none declared. Success: 200 [application/json]: type="object". | I22: Starfish represents this URL as /cloud/logs/{logType}; its enum includes radioPacketLog. Vulcan documents the concrete URL. Both reviewers report support. | J22: Retain both documentation representations. They describe the same concrete route for this log type. | K22: No Change Required | L22: No endpoint implementation change. In a unified index, link the concrete URL to the parameterized Starfish operation. Response-format and DELETE-enum questions are tracked in E-030 and E-029. | M22: None for this route-support finding. See E-029/E-030 for unresolved contracts. | N22: Not yet recorded | O22: Resolved | P22: Endpoint review, source 15, Excel row 21 | Q22: =HYPERLINK("Firmware_Change_Review.md#e-015","Open E-015") -> Open E-015 | R22: Concrete log URL is already represented | S22: Both reviewer statements confirm support; both operation definitions represent the concrete URL. This closure covers route presence only. Source limitation: Reviewers disagree on documented versus undocumented, not on support.
A23: E-016 | B23: Starfish: FX9600 supports this (documented) Kamali: supported in fx9600 undocumented | C23: /cloud/logs/syslog | D23: DELETE | E23: Both | F23: Starfish: path logType -> #/paths/~1cloud~1logs~1{logType}/parameters/0 Vulcan: No target field declared -> #/paths/~1cloud~1logs~1syslog/delete | G23: Documented DELETE /cloud/logs/{logType}. Purge Log. Parameters: path logType. Request: none declared. Success: 200 []: no body schema. | H23: Documented DELETE /cloud/logs/syslog. Purge Log. Parameters: none declared. Request: none declared. Success: 200 [application/json]: no body schema. | I23: Starfish represents this URL as /cloud/logs/{logType}; its enum includes syslog. Vulcan documents the concrete URL. Both reviewers report support. | J23: Retain both documentation representations. They describe the same concrete route for this log type. | K23: No Change Required | L23: No endpoint implementation change. In a unified index, link the concrete URL to the parameterized Starfish operation. Response-format and DELETE-enum questions are tracked in E-030 and E-029. | M23: None for this route-support finding. See E-029/E-030 for unresolved contracts. | N23: Not yet recorded | O23: Resolved | P23: Endpoint review, source 16, Excel row 22 | Q23: =HYPERLINK("Firmware_Change_Review.md#e-016","Open E-016") -> Open E-016 | R23: Concrete log URL is already represented | S23: Both reviewer statements confirm support; both operation definitions represent the concrete URL. This closure covers route presence only. Source limitation: Reviewers disagree on documented versus undocumented, not on support.
A24: E-017 | B24: Starfish: FX9600 supports this (documented) Kamali: supported in fx9600 undocumented | C24: /cloud/logs/syslog | D24: GET | E24: Both | F24: Starfish: path logType -> #/paths/~1cloud~1logs~1{logType}/parameters/0 Starfish: $ -> #/paths/~1cloud~1logs~1{logType}/get/responses/200/content/application~1gzip/schema Vulcan: $ -> #/components/schemas/GetLogsSyslogResponse Vulcan: $["binary"] -> #/components/schemas/GetLogsSyslogResponse/properties/binary Vulcan: $["filename"] -> #/components/schemas/GetLogsSyslogResponse/properties/filename | G24: Documented GET /cloud/logs/{logType}. Retrieve Log. Parameters: path logType. Request: none declared. Success: 200 [application/gzip]: type/constraints not specified here. | H24: Documented GET /cloud/logs/syslog. Retrieve Syslog. Parameters: none declared. Request: none declared. Success: 200 [application/json]: type="object". | I24: Starfish represents this URL as /cloud/logs/{logType}; its enum includes syslog. Vulcan documents the concrete URL. Both reviewers report support. | J24: Retain both documentation representations. They describe the same concrete route for this log type. | K24: No Change Required | L24: No endpoint implementation change. In a unified index, link the concrete URL to the parameterized Starfish operation. Response-format and DELETE-enum questions are tracked in E-030 and E-029. | M24: None for this route-support finding. See E-029/E-030 for unresolved contracts. | N24: Not yet recorded | O24: Resolved | P24: Endpoint review, source 17, Excel row 23 | Q24: =HYPERLINK("Firmware_Change_Review.md#e-017","Open E-017") -> Open E-017 | R24: Concrete log URL is already represented | S24: Both reviewer statements confirm support; both operation definitions represent the concrete URL. This closure covers route presence only. Source limitation: Reviewers disagree on documented versus undocumented, not on support.
A25: E-018 | B25: Starfish: Firmware confirms FX9600 does not support it. Kamali: not supported in fx9600 | C25: /cloud/networkInterfaces | D25: GET | E25: Both | F25: Starfish: Operation absent -> #/paths/~1cloud~1networkInterfaces/get Vulcan: $["availableNetworkInterfaces"] -> #/components/schemas/GetNetworkinterfacesResponse/properties/availableNetworkInterfaces Vulcan: $["availableNetworkInterfaces"][*] -> #/components/schemas/GetNetworkinterfacesResponse/properties/availableNetworkInterfaces/items | G25: No operation in supplied schema; implementation is not established by that absence. | H25: Documented GET /cloud/networkInterfaces. Retrieves network interfaces. Parameters: none declared. Request: none declared. Success: 200 [application/json]: type="object"; required=["availableNetworkInterfaces"]. | I25: Vulcan defines the operation and Starfish does not. Reviewer feedback supports that platform boundary. | J25: Retain the current platform-specific API scope. | K25: No Change Required | L25: Keep the endpoint limited to the documented platform. No cross-platform feature implementation is requested by the source comment. | M25: None unless the product requirement changes. A parity request would need a separate approved requirement. | N25: Not yet recorded | O25: Resolved | P25: Endpoint review, source 18, Excel row 24 | Q25: =HYPERLINK("Firmware_Change_Review.md#e-018","Open E-018") -> Open E-018 | R25: Intentional platform scope | S25: Repository path presence and reviewer platform-scope statement. For readerLocation, Starfish explicitly excludes FX9600; Kamali confirms FXR support without independently excluding FX9600.
A26: E-019 | B26: Starfish: FX9600 supports this (documented) Kamali: supported in fx9600 undocumented | C26: /cloud/pass-through | D26: PUT | E26: Starfish | F26: Starfish: Operation absent -> #/paths/~1cloud~1pass-through/put Vulcan: $ -> #/components/schemas/SetPassthruRequest Vulcan: $["component"] -> #/components/schemas/SetPassthruRequest/properties/component Vulcan: $["payload"] -> #/components/schemas/SetPassthruRequest/properties/payload | G26: No operation in supplied schema; implementation is not established by that absence. | H26: Documented PUT /cloud/pass-through. Pass-through command. Parameters: none declared. Request: type="object". Success: 200 [application/json]: type="object". | I26: Both reviewers report FX9600 support. The provided Starfish file omits PUT /cloud/pass-through although its app-specific pass-through operation exists. Vulcan accepts component and payload. | J26: Add documentation for the existing component operation without conflating it with /cloud/apps/{appname}/pass-through. | K26: Schema Update | L26: Locate the documented Starfish reference mentioned by its reviewer and obtain the accepted component payload before adding the missing operation to this file. | M26: For FX9600 component pass-through, are component="RC" and payload strings accepted at this exact URL? Supply the existing reference or a redacted transaction. | N26: Not yet recorded | O26: Open | P26: Endpoint review, source 19, Excel row 25 | Q26: =HYPERLINK("Firmware_Change_Review.md#e-019","Open E-019") -> Open E-019 | R26: Missing Starfish component pass-through documentation | S26: Repository schema and original reviewer statements; no live reader test supplied.
A27: E-020 | B27: Starfish: Firmware confirms FX9600 does not support it. Kamali: supported only in fxr90/60 | C27: /cloud/preSelection | D27: GET | E27: Both | F27: Starfish: Operation absent -> #/paths/~1cloud~1preSelection/get Vulcan: $["preSelection"] -> #/components/schemas/GetPreSelectionResponse/properties/preSelection | G27: No operation in supplied schema; implementation is not established by that absence. | H27: Documented GET /cloud/preSelection. Returns whether the rxSawFilter is enabled or disabled. Parameters: none declared. Request: none declared. Success: 200 [application/json]: type="object". | I27: Vulcan defines the operation and Starfish does not. Reviewer feedback supports that platform boundary. | J27: Retain the current platform-specific API scope. | K27: No Change Required | L27: Keep the endpoint limited to the documented platform. No cross-platform feature implementation is requested by the source comment. | M27: None unless the product requirement changes. A parity request would need a separate approved requirement. | N27: Not yet recorded | O27: Resolved | P27: Endpoint review, source 20, Excel row 26 | Q27: =HYPERLINK("Firmware_Change_Review.md#e-020","Open E-020") -> Open E-020 | R27: Intentional platform scope | S27: Repository path presence and reviewer platform-scope statement. For readerLocation, Starfish explicitly excludes FX9600; Kamali confirms FXR support without independently excluding FX9600.
A28: E-021 | B28: Starfish: Firmware confirms FX9600 does not support it. Kamali: supported only in fxr90/60 | C28: /cloud/preSelection | D28: PUT | E28: Both | F28: Starfish: Operation absent -> #/paths/~1cloud~1preSelection/put Vulcan: $["preSelection"] -> #/components/schemas/SetPreSelectionRequest/properties/preSelection | G28: No operation in supplied schema; implementation is not established by that absence. | H28: Documented PUT /cloud/preSelection. Enables or disables the rxSawFilter. Parameters: none declared. Request: type="object". Success: 200 [application/json]: type="string". | I28: Vulcan defines the operation and Starfish does not. Reviewer feedback supports that platform boundary. | J28: Retain the current platform-specific API scope. | K28: No Change Required | L28: Keep the endpoint limited to the documented platform. No cross-platform feature implementation is requested by the source comment. | M28: None unless the product requirement changes. A parity request would need a separate approved requirement. | N28: Not yet recorded | O28: Resolved | P28: Endpoint review, source 21, Excel row 27 | Q28: =HYPERLINK("Firmware_Change_Review.md#e-021","Open E-021") -> Open E-021 | R28: Intentional platform scope | S28: Repository path presence and reviewer platform-scope statement. For readerLocation, Starfish explicitly excludes FX9600; Kamali confirms FXR support without independently excluding FX9600.
A29: E-022 | B29: Starfish: FX9600 supports this internally (undocumented) API is not exposed to outside Kamali: not supported in fx9600 (local rest mapping missing,mqtt available) | C29: /cloud/readPoints | D29: GET | E29: Starfish | F29: Starfish: Operation absent -> #/paths/~1cloud~1readPoints/get Vulcan: $ -> #/components/schemas/GetReadpointsResponse Vulcan: $[*] -> #/components/schemas/GetReadpointsResponse/items | G29: No operation in supplied schema; implementation is not established by that absence. | H29: Documented GET /cloud/readPoints. Gets the read points on the reader. Parameters: none declared. Request: none declared. Success: 200 [application/json]: type="array". | I29: Starfish says readPoints is internal and not exposed externally; Kamali reports missing local REST mapping and available MQTT. Only Vulcan has this public path. | J29: Keep FX9600 out of the public REST reference unless external exposure is explicitly required and released. | K29: Developer Clarification | L29: Record the exposure decision. If internal/MQTT-only is intentional, close as No Change Required. If external REST is required, define a mapping change and its release. | M29: Is FX9600 GET /cloud/readPoints intentionally internal/MQTT-only, or must it become a public authenticated local REST endpoint? If required, identify the output contract and release. | N29: Not yet recorded | O29: Open | P29: Endpoint review, source 22, Excel row 28 | Q29: =HYPERLINK("Firmware_Change_Review.md#e-022","Open E-022") -> Open E-022 | R29: Internal read-points support versus public REST | S29: Repository schema and original reviewer statements; no live reader test supplied. Source limitation: Internal support and public REST availability are different.
A30: E-023 | B30: Starfish: Firmware confirms FX9600 does not support it. Kamali: supported in fxr90/60 | C30: /cloud/readerLocation | D30: GET | E30: Both | F30: Starfish: Operation absent -> #/paths/~1cloud~1readerLocation/get Vulcan: $["lastReportedTime"] -> #/components/schemas/GetGpsCoordinatesResponse/properties/lastReportedTime Vulcan: $["latitude"] -> #/components/schemas/GetGpsCoordinatesResponse/properties/latitude Vulcan: $["longitude"] -> #/components/schemas/GetGpsCoordinatesResponse/properties/longitude Vulcan: $["satellitesUsed"] -> #/components/schemas/GetGpsCoordinatesResponse/properties/satellitesUsed | G30: No operation in supplied schema; implementation is not established by that absence. | H30: Documented GET /cloud/readerLocation. Gets the GPS coordinates (lat/long). Parameters: none declared. Request: none declared. Success: 200 [application/json]: type="object". | I30: Vulcan defines the operation and Starfish does not. Reviewer feedback supports that platform boundary. | J30: Retain the current platform-specific API scope. | K30: No Change Required | L30: Keep the endpoint limited to the documented platform. No cross-platform feature implementation is requested by the source comment. | M30: None unless the product requirement changes. A parity request would need a separate approved requirement. | N30: Not yet recorded | O30: Resolved | P30: Endpoint review, source 23, Excel row 29 | Q30: =HYPERLINK("Firmware_Change_Review.md#e-023","Open E-023") -> Open E-023 | R30: Intentional platform scope | S30: Repository path presence and reviewer platform-scope statement. For readerLocation, Starfish explicitly excludes FX9600; Kamali confirms FXR support without independently excluding FX9600. Source limitation: Kamali confirms FXR support but does not explicitly deny FX9600 support.
A31: E-024 | B31: Starfish: FX9600 supports this (undocumented) FX9600 currently implementation is going on Kamali: supported in fxr90/60 . | C31: /cloud/region | D31: PUT | E31: Starfish | F31: Starfish: Operation absent -> #/paths/~1cloud~1region/put Vulcan: $ -> #/components/schemas/SetRegionRequest Vulcan: $["country"] -> #/components/schemas/SetRegionRequest/properties/country Vulcan: $["standardname"] -> #/components/schemas/SetRegionRequest/properties/standardname Vulcan: $["isLBT"] -> #/components/schemas/SetRegionRequest/properties/isLBT Vulcan: $["channeldata"] -> #/components/schemas/SetRegionRequest/properties/channeldata Vulcan: $["channeldata"][*] -> #/components/schemas/SetRegionRequest/properties/channeldata/items | G31: No operation in supplied schema; implementation is not established by that absence. | H31: Documented PUT /cloud/region. Update region information. Parameters: none declared. Request: type="object"; required=["country","standardname"]. Success: 200 [application/json]: type="string". | I31: Starfish feedback simultaneously says supported and implementation ongoing. PUT /cloud/region is absent in the supplied Starfish file. Vulcan defines country, standardname, isLBT and channeldata. | J31: Establish whether a released FX9600 setter exists and which request keys it accepts. | K31: Developer Clarification | L31: Obtain the implementation ticket, release state and exact FX9600 request. Keep any future support labeled unreleased until confirmed. | M31: Has FX9600 PUT /cloud/region shipped? Provide the firmware version and accepted keys, or identify the pending implementation and approved acceptance criteria. | N31: Not yet recorded | O31: Open | P31: Endpoint review, source 24, Excel row 30 | Q31: =HYPERLINK("Firmware_Change_Review.md#e-024","Open E-024") -> Open E-024 | R31: Region setter release status | S31: Repository schema and original reviewer statements; no live reader test supplied. Source limitation: Starfish says both supported and implementation in progress; Kamali only confirms FXR support.
A32: E-025 | B32: Starfish: Firmware confirms FX9600 does not support it. Kamali: supported only in fxr60 | C32: /cloud/stack-led | D32: GET | E32: Vulcan | F32: Starfish: Operation absent -> #/paths/~1cloud~1stack-led/get Vulcan: $["status"] -> #/components/schemas/GetStackledResponse/oneOf/0/properties/status Vulcan: $["status"] -> #/components/schemas/GetStackledResponse/oneOf/1/properties/status | G32: No operation in supplied schema; implementation is not established by that absence. | H32: Documented GET /cloud/stack-led. Retrieves stack LED state. Parameters: none declared. Request: none declared. Success: 200 [application/json]: type/constraints not specified here. | I32: Kamali restricts support to FXR60; the current narrative is more specific: FXR60 Premium only, excluding other FXR60 variants and FXR90. Starfish omits it. | J32: Retain FXR60 Premium applicability as documented. | K32: No Change Required | L32: No additional scope correction is needed in this snapshot. Preserve the SKU restriction in the unified index. | M32: None for the requested FXR90 exclusion. Reopen only if the Premium SKU restriction is disputed. | N32: Not yet recorded | O32: Resolved | P32: Endpoint review, source 25, Excel row 31 | Q32: =HYPERLINK("Firmware_Change_Review.md#e-025","Open E-025") -> Open E-025 | R32: Stack LED scope already narrowed | S32: Both current operation descriptions explicitly exclude FXR90; reviewer comments agree on FXR60 scope.
A33: E-026 | B33: Starfish: Firmware confirms FX9600 does not support it. Kamali: supported only in fxr60 | C33: /cloud/stack-led | D33: PUT | E33: Vulcan | F33: Starfish: Operation absent -> #/paths/~1cloud~1stack-led/put Vulcan: $["color"] -> #/components/schemas/SetStackledRequest/properties/color Vulcan: $["brightness"] -> #/components/schemas/SetStackledRequest/properties/brightness Vulcan: $["flash"] -> #/components/schemas/SetStackledRequest/properties/flash Vulcan: $["seconds"] -> #/components/schemas/SetStackledRequest/properties/seconds | G33: No operation in supplied schema; implementation is not established by that absence. | H33: Documented PUT /cloud/stack-led. Updates stack LED state. Parameters: none declared. Request: type="object"; required=["color","flash","seconds"]. Success: 200 [application/json]: type="string". | I33: Kamali restricts support to FXR60; the current narrative is more specific: FXR60 Premium only, excluding other FXR60 variants and FXR90. Starfish omits it. | J33: Retain FXR60 Premium applicability as documented. | K33: No Change Required | L33: No additional scope correction is needed in this snapshot. Preserve the SKU restriction in the unified index. | M33: None for the requested FXR90 exclusion. Reopen only if the Premium SKU restriction is disputed. | N33: Not yet recorded | O33: Resolved | P33: Endpoint review, source 26, Excel row 32 | Q33: =HYPERLINK("Firmware_Change_Review.md#e-026","Open E-026") -> Open E-026 | R33: Stack LED scope already narrowed | S33: Both current operation descriptions explicitly exclude FXR90; reviewer comments agree on FXR60 scope.
